<?xml version="1.0" encoding="UTF-8"?>
<testng-results ignored="6" total="8" passed="1" failed="1" skipped="0">
  <reporter-output>
  </reporter-output>
  <suite started-at="2022-05-09T15:41:03 IST" name="Suite" finished-at="2022-05-09T15:41:03 IST" duration-ms="44">
    <groups>
      <group name="add">
        <method signature="Testcases.testfail()[pri:0, instance:com.calculator.Testcases@5223e5ee]" name="testfail" class="com.calculator.Testcases"/>
        <method signature="Testcases.testpass()[pri:0, instance:com.calculator.Testcases@5223e5ee]" name="testpass" class="com.calculator.Testcases"/>
      </group> <!-- add -->
    </groups>
    <test started-at="2022-05-09T15:41:03 IST" name="Test" finished-at="2022-05-09T15:41:03 IST" duration-ms="44">
      <class name="com.calculator.Testcases">
        <test-method signature="testfail()[pri:0, instance:com.calculator.Testcases@5223e5ee]" started-at="2022-05-09T15:41:03 IST" name="testfail" finished-at="2022-05-09T15:41:03 IST" duration-ms="13" status="FAIL">
          <exception class="java.lang.AssertionError">
            <message>
              <![CDATA[expected [10.0] but found [30.0]]]>
            </message>
            <full-stacktrace>
              <![CDATA[java.lang.AssertionError: expected [10.0] but found [30.0]
at org.testng.Assert.fail(Assert.java:99)
at org.testng.Assert.failNotEquals(Assert.java:1037)
at org.testng.Assert.assertEquals(Assert.java:701)
at org.testng.Assert.assertEquals(Assert.java:712)
at com.calculator.Testcases.testfail(Testcases.java:27)
at java.base/jdk.internal.reflect.DirectMethodHandleAccessor.invoke(DirectMethodHandleAccessor.java:104)
at java.base/java.lang.reflect.Method.invoke(Method.java:577)
at org.testng.internal.MethodInvocationHelper.invokeMethod(MethodInvocationHelper.java:133)
at org.testng.internal.TestInvoker.invokeMethod(TestInvoker.java:598)
at org.testng.internal.TestInvoker.invokeTestMethod(TestInvoker.java:173)
at org.testng.internal.MethodRunner.runInSequence(MethodRunner.java:46)
at org.testng.internal.TestInvoker$MethodInvocationAgent.invoke(TestInvoker.java:824)
at org.testng.internal.TestInvoker.invokeTestMethods(TestInvoker.java:146)
at org.testng.internal.TestMethodWorker.invokeTestMethods(TestMethodWorker.java:146)
at org.testng.internal.TestMethodWorker.run(TestMethodWorker.java:128)
at java.base/java.util.concurrent.ThreadPoolExecutor.runWorker(ThreadPoolExecutor.java:1136)
at java.base/java.util.concurrent.ThreadPoolExecutor$Worker.run(ThreadPoolExecutor.java:635)
at java.base/java.lang.Thread.run(Thread.java:833)
]]>
            </full-stacktrace>
          </exception> <!-- java.lang.AssertionError -->
          <reporter-output>
          </reporter-output>
        </test-method> <!-- testfail -->
        <test-method signature="testpass()[pri:0, instance:com.calculator.Testcases@5223e5ee]" started-at="2022-05-09T15:41:03 IST" name="testpass" finished-at="2022-05-09T15:41:03 IST" duration-ms="12" status="PASS">
          <reporter-output>
          </reporter-output>
        </test-method> <!-- testpass -->
      </class> <!-- com.calculator.Testcases -->
    </test> <!-- Test -->
  </suite> <!-- Suite -->
</testng-results>
