<?xml version="1.0" encoding="UTF-8"?>
<!-- Generated by org.testng.reporters.JUnitReportReporter -->
<testsuite hostname="EPINBANW03CF" failures="1" tests="2" name="com.calculator.Testcases" time="0.025" errors="0" timestamp="2022-05-09T15:41:03 IST" skipped="0">
  <testcase classname="com.calculator.Testcases" name="testfail" time="0.013">
    <failure message="expected [10.0] but found [30.0]" type="java.lang.AssertionError">
      <![CDATA[java.lang.AssertionError: expected [10.0] but found [30.0]
at org.testng.Assert.fail(Assert.java:99)
at org.testng.Assert.failNotEquals(Assert.java:1037)
at org.testng.Assert.assertEquals(Assert.java:701)
at org.testng.Assert.assertEquals(Assert.java:712)
at com.calculator.Testcases.testfail(Testcases.java:27)
at java.base/jdk.internal.reflect.DirectMethodHandleAccessor.invoke(DirectMethodHandleAccessor.java:104)
at java.base/java.lang.reflect.Method.invoke(Method.java:577)
at org.testng.internal.MethodInvocationHelper.invokeMethod(MethodInvocationHelper.java:133)
at org.testng.internal.TestInvoker.invokeMethod(TestInvoker.java:598)
at org.testng.internal.TestInvoker.invokeTestMethod(TestInvoker.java:173)
at org.testng.internal.MethodRunner.runInSequence(MethodRunner.java:46)
at org.testng.internal.TestInvoker$MethodInvocationAgent.invoke(TestInvoker.java:824)
at org.testng.internal.TestInvoker.invokeTestMethods(TestInvoker.java:146)
at org.testng.internal.TestMethodWorker.invokeTestMethods(TestMethodWorker.java:146)
at org.testng.internal.TestMethodWorker.run(TestMethodWorker.java:128)
at java.base/java.util.concurrent.ThreadPoolExecutor.runWorker(ThreadPoolExecutor.java:1136)
at java.base/java.util.concurrent.ThreadPoolExecutor$Worker.run(ThreadPoolExecutor.java:635)
at java.base/java.lang.Thread.run(Thread.java:833)
]]>
    </failure>
  </testcase> <!-- testfail -->
  <system-out/>
  <testcase classname="com.calculator.Testcases" name="testpass" time="0.012"/>
  <system-out/>
</testsuite> <!-- com.calculator.Testcases -->
